Workbook
Name _5111cda8_STF_Fuss_1_CN1: #REF!
Name _5111cda8_STF_Gesamtsumme_1_CN1: #REF!
Name _5111cda8_STF_Gesamtsumme_1_CN2: #REF!
Name _5111cda8_STF_Koerper_1_CN1: #REF!
Name _5111cda8_STF_Koerper_1_CN3: #REF!
Name _5111cda8_STF_Koerper_1_CN4: #REF!
Name _5111cda8_STF_Koerper_1_CN5: #REF!
Name _5111cda8_STF_Koerper_1_CN6: #REF!
Name _5111cda8_STF_Koerper_1_CN7: #REF!
Name _5111cda8_STF_Koerper_1_CN8: #REF!
Name _5111cda8_STF_Tabellenkopf_1_CN1: #REF!
Name _5111cda8_STF_Titel_1_CN1: #REF!
Name _5111cda8_STF_Vorspalte_1_CN1: #REF!
Name _CST2006: #REF!
Name _CST2008: #REF!
Name _TAB7: #REF!
Name b: #N/A
Name bébé: #REF!
Name ChoixTraçage: #REF!
Name COMPTE_D_EXPLOITATION_PAR_BRANCHE: #REF!
Name CST: #REF!
Name CST_2006: #REF!
Name D: {#N/A,#N/A,FALSE,"bel";#N/A,#N/A,FALSE,"neth"}
Name DatesGraphiques: CHOOSE(TableauGraphique,#REF!,#REF!)
Name Données_brutes: #REF!
Name Données_volume: #REF!
Name Données_volume_2: #REF!
Name Données_volume_3: #REF!
Name Données_volume_5: #REF!
Name Donnéesbrutes: #REF!
Name Donnéesbrutes_2: #REF!
Name Donnéesbrutes_3: #REF!
Name Donnéesbrutes_5: #REF!
Name DonnéesCNAM: #REF!
Name DonnéesCNAM_2: #REF!
Name DonnéesCNAM_3: #REF!
Name DonnéesCNAM_5: #REF!
Name DonnéesCVS: #REF!
Name DonnéesDemetra_CT: #REF!
Name DonnéesDemetra_CT_2: #REF!
Name DonnéesDemetra_CT_3: #REF!
Name DonnéesDemetra_CT_5: #REF!
Name Fra: "Graphique 2"
Name Graphiques: #REF!
Name IQ_CH: 110000
Name IQ_DAILY: 500000
Name IQ_FH: 100000
Name IQ_MONTH: 15000
Name IQ_WEEK: 50000
Name JHTK: #REF!
Name k: CHOOSE([0]!ll,#REF!,#REF!)
Name KilométrageDébut: #REF!
Name kk: CHOOSE(TableauGraphique,#REF!,#REF!)
Name nom: #REF!
Name NP: #REF!
Name NP_Description: #REF!
Name poupou: #REF!
Name PT_commencerlarangée: ROW(INDEX(#REF!,MATCH("*",#REF!,0),1))+1
Name PT_rangéedextrémité: COUNTA(#REF!)+PT_commencerlarangée-3
Name rien: #REF!

Sheet Cover
D4: Schéma directeur / Plan stratégique à 10 ans cloud et datacenters
D5: Modélisation de la demande IT Horizon 2035

Sheet 0_Sliding
B2: Sliding
B6: A. | D6: Total 3 scénarios
E8: 2026 | F8: =E8+1 -> 2027 | G8: =F8+1 -> 2028 | H8: =G8+1 -> 2029 | I8: =H8+1 -> 2030 | J8: =I8+1 -> 2031 | K8: =J8+1 -> 2032 | L8: =K8+1 -> 2033 | M8: =L8+1 -> 2034 | N8: =M8+1 -> 2035 | P8: CAGR
D10: Estimation basse | E10: ='3_Output'!$C$8 -> 2.47032 | F10: =E10*(1+_xlfn.RRI($N$8-$E$8,'3_Output'!$C$8,'3_Output'!$C$9)) -> 2.5998048 | G10: =F10*(1+_xlfn.RRI($N$8-$E$8,'3_Output'!$C$8,'3_Output'!$C$9)) -> 2.7360767 | H10: =G10*(1+_xlfn.RRI($N$8-$E$8,'3_Output'!$C$8,'3_Output'!$C$9)) -> 2.8794915 | I10: =H10*(1+_xlfn.RRI($N$8-$E$8,'3_Output'!$C$8,'3_Output'!$C$9)) -> 3.0304235 | J10: =I10*(1+_xlfn.RRI($N$8-$E$8,'3_Output'!$C$8,'3_Output'!$C$9)) -> 3.1892669 | K10: =J10*(1+_xlfn.RRI($N$8-$E$8,'3_Output'!$C$8,'3_Output'!$C$9)) -> 3.3564362 | L10: =K10*(1+_xlfn.RRI($N$8-$E$8,'3_Output'!$C$8,'3_Output'!$C$9)) -> 3.5323678 | M10: =L10*(1+_xlfn.RRI($N$8-$E$8,'3_Output'!$C$8,'3_Output'!$C$9)) -> 3.7175212 | N10: =M10*(1+_xlfn.RRI($N$8-$E$8,'3_Output'!$C$8,'3_Output'!$C$9)) -> 3.9123795 | P10: =_xlfn.RRI($N$8-$E$8,E10,N10) -> 0.052416212 | R10: =N10='3_Output'!C9 -> TRUE
D11: Intermediate estimate | E11: ='3_Output'!$C$8 -> 2.47032 | F11: =E11*(1+_xlfn.RRI($N$8-$E$8,'3_Output'!$D$8,'3_Output'!$D$9)) -> 2.7346632 | G11: =F11*(1+_xlfn.RRI($N$8-$E$8,'3_Output'!$D$8,'3_Output'!$D$9)) -> 3.0272931 | H11: =G11*(1+_xlfn.RRI($N$8-$E$8,'3_Output'!$D$8,'3_Output'!$D$9)) -> 3.3512367 | I11: =H11*(1+_xlfn.RRI($N$8-$E$8,'3_Output'!$D$8,'3_Output'!$D$9)) -> 3.7098447 | J11: =I11*(1+_xlfn.RRI($N$8-$E$8,'3_Output'!$D$8,'3_Output'!$D$9)) -> 4.1068265 | K11: =J11*(1+_xlfn.RRI($N$8-$E$8,'3_Output'!$D$8,'3_Output'!$D$9)) -> 4.5462884 | L11: =K11*(1+_xlfn.RRI($N$8-$E$8,'3_Output'!$D$8,'3_Output'!$D$9)) -> 5.0327761 | M11: =L11*(1+_xlfn.RRI($N$8-$E$8,'3_Output'!$D$8,'3_Output'!$D$9)) -> 5.5713218 | N11: =M11*(1+_xlfn.RRI($N$8-$E$8,'3_Output'!$D$8,'3_Output'!$D$9)) -> 6.1674959 | P11: =_xlfn.RRI($N$8-$E$8,E11,N11) -> 0.10700767 | R11: =N11='3_Output'!D9 -> TRUE
D12: Estimation haute | E12: ='3_Output'!$C$8 -> 2.47032 | F12: =E12*(1+_xlfn.RRI($N$8-$E$8,'3_Output'!$E$8,'3_Output'!$E$9)) -> 2.8228601 | G12: =F12*(1+_xlfn.RRI($N$8-$E$8,'3_Output'!$E$8,'3_Output'!$E$9)) -> 3.2257112 | H12: =G12*(1+_xlfn.RRI($N$8-$E$8,'3_Output'!$E$8,'3_Output'!$E$9)) -> 3.6860534 | I12: =H12*(1+_xlfn.RRI($N$8-$E$8,'3_Output'!$E$8,'3_Output'!$E$9)) -> 4.2120911 | J12: =I12*(1+_xlfn.RRI($N$8-$E$8,'3_Output'!$E$8,'3_Output'!$E$9)) -> 4.8131998 | K12: =J12*(1+_xlfn.RRI($N$8-$E$8,'3_Output'!$E$8,'3_Output'!$E$9)) -> 5.5000929 | L12: =K12*(1+_xlfn.RRI($N$8-$E$8,'3_Output'!$E$8,'3_Output'!$E$9)) -> 6.2850127 | M12: =L12*(1+_xlfn.RRI($N$8-$E$8,'3_Output'!$E$8,'3_Output'!$E$9)) -> 7.1819486 | N12: =M12*(1+_xlfn.RRI($N$8-$E$8,'3_Output'!$E$8,'3_Output'!$E$9)) -> 8.2068865 | P12: =_xlfn.RRI($N$8-$E$8,E12,N12) -> 0.14271028 | R12: =N12='3_Output'!E9 -> TRUE
B15: B. | D15: Total 3 scénarios
F17: Scénario bas | G17: Scénario central | H17: Scénario haut
E18: 2026 | F18: Scénario bas - 2035 | G18: Scénario central - 2035 | H18: Scénario haut - 2035
D20: Privé | E20: =SUM('2_Calculs'!F14:F16)/10^3 -> 2.20032 | F20: =SUMIFS('2_Calculs'!$L:$L,'2_Calculs'!$B:$B,F$17,'2_Calculs'!$C:$C,$D20)/10^3 -> 3.2510733 | G20: =SUMIFS('2_Calculs'!$L:$L,'2_Calculs'!$B:$B,G$17,'2_Calculs'!$C:$C,$D20)/10^3 -> 5.2996684 | H20: =SUMIFS('2_Calculs'!$L:$L,'2_Calculs'!$B:$B,H$17,'2_Calculs'!$C:$C,$D20)/10^3 -> 6.9466397
D21: Public | E21: =SUM('2_Calculs'!F9:F13)/10^3 -> 0.27 | F21: =SUMIFS('2_Calculs'!$L:$L,'2_Calculs'!$B:$B,F$17,'2_Calculs'!$C:$C,$D21)/10^3 -> 0.66130622 | G21: =SUMIFS('2_Calculs'!$L:$L,'2_Calculs'!$B:$B,G$17,'2_Calculs'!$C:$C,$D21)/10^3 -> 0.86782755 | H21: =SUMIFS('2_Calculs'!$L:$L,'2_Calculs'!$B:$B,H$17,'2_Calculs'!$C:$C,$D21)/10^3 -> 1.2602468
B24: C. | D24: Public
B26: 1 | D26: Evolution
E28: 2026 | F28: 2027 | G28: 2028 | H28: 2029 | I28: 2030 | J28: 2031 | K28: 2032 | L28: 2033 | M28: 2034 | N28: 2035 | P28: CAGR
D30: Estimation basse | E30: =SUM('2_Calculs'!$F$9:$F$13) -> 270 | F30: =E30*(1+_xlfn.RRI($N$28-$E$28,$E$30,SUM('2_Calculs'!$L$59:$L$63))) -> 298.25676 | G30: =F30*(1+_xlfn.RRI($N$28-$E$28,$E$30,SUM('2_Calculs'!$L$59:$L$63))) -> 329.47073 | H30: =G30*(1+_xlfn.RRI($N$28-$E$28,$E$30,SUM('2_Calculs'!$L$59:$L$63))) -> 363.95139 | I30: =H30*(1+_xlfn.RRI($N$28-$E$28,$E$30,SUM('2_Calculs'!$L$59:$L$63))) -> 402.0406 | J30: =I30*(1+_xlfn.RRI($N$28-$E$28,$E$30,SUM('2_Calculs'!$L$59:$L$63))) -> 444.11604 | K30: =J30*(1+_xlfn.RRI($N$28-$E$28,$E$30,SUM('2_Calculs'!$L$59:$L$63))) -> 490.59486 | L30: =K30*(1+_xlfn.RRI($N$28-$E$28,$E$30,SUM('2_Calculs'!$L$59:$L$63))) -> 541.93791 | M30: =L30*(1+_xlfn.RRI($N$28-$E$28,$E$30,SUM('2_Calculs'!$L$59:$L$63))) -> 598.65425 | N30: =M30*(1+_xlfn.RRI($N$28-$E$28,$E$30,SUM('2_Calculs'!$L$59:$L$63))) -> 661.30622 | P30: =_xlfn.RRI($N$8-$E$8,E30,N30) -> 0.10465468 | R30: =N30=SUM('2_Calculs'!L59:L63) -> TRUE
D31: Estimation centrale | E31: =SUM('2_Calculs'!$F$9:$F$13) -> 270 | F31: =E31*(1+_xlfn.RRI($N$28-$E$28,$E$30,SUM('2_Calculs'!$L$74:$L$78))) -> 307.40069 | G31: =F31*(1+_xlfn.RRI($N$28-$E$28,$E$30,SUM('2_Calculs'!$L$74:$L$78))) -> 349.98216 | H31: =G31*(1+_xlfn.RRI($N$28-$E$28,$E$30,SUM('2_Calculs'!$L$74:$L$78))) -> 398.46207 | I31: =H31*(1+_xlfn.RRI($N$28-$E$28,$E$30,SUM('2_Calculs'!$L$74:$L$78))) -> 453.65746 | J31: =I31*(1+_xlfn.RRI($N$28-$E$28,$E$30,SUM('2_Calculs'!$L$74:$L$78))) -> 516.49858 | K31: =J31*(1+_xlfn.RRI($N$28-$E$28,$E$30,SUM('2_Calculs'!$L$74:$L$78))) -> 588.04452 | L31: =K31*(1+_xlfn.RRI($N$28-$E$28,$E$30,SUM('2_Calculs'!$L$74:$L$78))) -> 669.50108 | M31: =L31*(1+_xlfn.RRI($N$28-$E$28,$E$30,SUM('2_Calculs'!$L$74:$L$78))) -> 762.24109 | N31: =M31*(1+_xlfn.RRI($N$28-$E$28,$E$30,SUM('2_Calculs'!$L$74:$L$78))) -> 867.82755 | P31: =_xlfn.RRI($N$8-$E$8,E31,N31) -> 0.13852107 | R31: =N31=SUM('2_Calculs'!L74:L78) -> TRUE
D32: Estimation haute | E32: =SUM('2_Calculs'!$F$9:$F$13) -> 270 | F32: =E32*(1+_xlfn.RRI($N$28-$E$28,$E$30,SUM('2_Calculs'!$L$89:$L$93))) -> 320.41092 | G32: =F32*(1+_xlfn.RRI($N$28-$E$28,$E$30,SUM('2_Calculs'!$L$89:$L$93))) -> 380.23391 | H32: =G32*(1+_xlfn.RRI($N$28-$E$28,$E$30,SUM('2_Calculs'!$L$89:$L$93))) -> 451.22627 | I32: =H32*(1+_xlfn.RRI($N$28-$E$28,$E$30,SUM('2_Calculs'!$L$89:$L$93))) -> 535.47342 | J32: =I32*(1+_xlfn.RRI($N$28-$E$28,$E$30,SUM('2_Calculs'!$L$89:$L$93))) -> 635.45011 | K32: =J32*(1+_xlfn.RRI($N$28-$E$28,$E$30,SUM('2_Calculs'!$L$89:$L$93))) -> 754.09315 | L32: =K32*(1+_xlfn.RRI($N$28-$E$28,$E$30,SUM('2_Calculs'!$L$89:$L$93))) -> 894.88769 | M32: =L32*(1+_xlfn.RRI($N$28-$E$28,$E$30,SUM('2_Calculs'!$L$89:$L$93))) -> 1061.9696 | N32: =M32*(1+_xlfn.RRI($N$28-$E$28,$E$30,SUM('2_Calculs'!$L$89:$L$93))) -> 1260.2468 | P32: =_xlfn.RRI($N$8-$E$8,E32,N32) -> 0.18670709 | R32: =N32=SUM('2_Calculs'!L89:L93) -> TRUE
B34: 2 | D34: Répartition
E36: Scénario haut
D38: DITN | E38: ='2_Calculs'!L92 -> 226.89062
D39: Pompiers | E39: ='2_Calculs'!L91 -> 74.217607
D40: DSP | E40: ='2_Calculs'!L89 -> 427.71614
D41: CHPG | E41: ='2_Calculs'!L93 -> 474.69979
D42: Autres entités | E42: ='2_Calculs'!L90 -> 56.722656
B46: D. | D46: Privé
R47: 500 | S47: =0.438 -> 0.438
B48: 1 | D48: Evolution | R48: =R47/S47 -> 1141.5525 | S48: 1
E50: 2026 | F50: 2027 | G50: 2028 | H50: 2029 | I50: 2030 | J50: 2031 | K50: 2032 | L50: 2033 | M50: 2034 | N50: 2035 | P50: CAGR
D52: Estimation basse | E52: =SUM('2_Calculs'!$F$14:$F$16) -> 2200.32 | F52: =E52*(1+_xlfn.RRI($N$28-$E$28,$E$52,SUM('2_Calculs'!$L$64:$L$66))) -> 2297.8609 | G52: =F52*(1+_xlfn.RRI($N$28-$E$28,$E$52,SUM('2_Calculs'!$L$64:$L$66))) -> 2399.7257 | H52: =G52*(1+_xlfn.RRI($N$28-$E$28,$E$52,SUM('2_Calculs'!$L$64:$L$66))) -> 2506.1063 | I52: =H52*(1+_xlfn.RRI($N$28-$E$28,$E$52,SUM('2_Calculs'!$L$64:$L$66))) -> 2617.2027 | J52: =I52*(1+_xlfn.RRI($N$28-$E$28,$E$52,SUM('2_Calculs'!$L$64:$L$66))) -> 2733.2241 | K52: =J52*(1+_xlfn.RRI($N$28-$E$28,$E$52,SUM('2_Calculs'!$L$64:$L$66))) -> 2854.3888 | L52: =K52*(1+_xlfn.RRI($N$28-$E$28,$E$52,SUM('2_Calculs'!$L$64:$L$66))) -> 2980.9247 | M52: =L52*(1+_xlfn.RRI($N$28-$E$28,$E$52,SUM('2_Calculs'!$L$64:$L$66))) -> 3113.07 | N52: =M52*(1+_xlfn.RRI($N$28-$E$28,$E$52,SUM('2_Calculs'!$L$64:$L$66))) -> 3251.0733 | P52: =_xlfn.RRI($N$8-$E$8,E52,N52) -> 0.044330303 | R52: =N52=SUM('2_Calculs'!L64:L66) -> FALSE
D53: Estimation centrale | E53: =SUM('2_Calculs'!$F$14:$F$16) -> 2200.32 | F53: =E53*(1+_xlfn.RRI($N$28-$E$28,$E$52,SUM('2_Calculs'!$L$79:$L$81))) -> 2426.0734 | G53: =F53*(1+_xlfn.RRI($N$28-$E$28,$E$52,SUM('2_Calculs'!$L$79:$L$81))) -> 2674.9892 | H53: =G53*(1+_xlfn.RRI($N$28-$E$28,$E$52,SUM('2_Calculs'!$L$79:$L$81))) -> 2949.4438 | I53: =H53*(1+_xlfn.RRI($N$28-$E$28,$E$52,SUM('2_Calculs'!$L$79:$L$81))) -> 3252.0576 | J53: =I53*(1+_xlfn.RRI($N$28-$E$28,$E$52,SUM('2_Calculs'!$L$79:$L$81))) -> 3585.7195 | K53: =J53*(1+_xlfn.RRI($N$28-$E$28,$E$52,SUM('2_Calculs'!$L$79:$L$81))) -> 3953.6153 | L53: =K53*(1+_xlfn.RRI($N$28-$E$28,$E$52,SUM('2_Calculs'!$L$79:$L$81))) -> 4359.2573 | M53: =L53*(1+_xlfn.RRI($N$28-$E$28,$E$52,SUM('2_Calculs'!$L$79:$L$81))) -> 4806.5183 | N53: =M53*(1+_xlfn.RRI($N$28-$E$28,$E$52,SUM('2_Calculs'!$L$79:$L$81))) -> 5299.6684 | P53: =_xlfn.RRI($N$8-$E$8,E53,N53) -> 0.10260027 | R53: =N53=SUM('2_Calculs'!L79:L81) -> TRUE
D54: Estimation haute | E54: =SUM('2_Calculs'!$F$14:$F$16) -> 2200.32 | F54: =E54*(1+_xlfn.RRI($N$28-$E$28,$E$52,SUM('2_Calculs'!$L$94:$L$96))) -> 2500.1289 | G54: =F54*(1+_xlfn.RRI($N$28-$E$28,$E$52,SUM('2_Calculs'!$L$94:$L$96))) -> 2840.7888 | H54: =G54*(1+_xlfn.RRI($N$28-$E$28,$E$52,SUM('2_Calculs'!$L$94:$L$96))) -> 3227.8659 | I54: =H54*(1+_xlfn.RRI($N$28-$E$28,$E$52,SUM('2_Calculs'!$L$94:$L$96))) -> 3667.6851 | J54: =I54*(1+_xlfn.RRI($N$28-$E$28,$E$52,SUM('2_Calculs'!$L$94:$L$96))) -> 4167.4326 | K54: =J54*(1+_xlfn.RRI($N$28-$E$28,$E$52,SUM('2_Calculs'!$L$94:$L$96))) -> 4735.2742 | L54: =K54*(1+_xlfn.RRI($N$28-$E$28,$E$52,SUM('2_Calculs'!$L$94:$L$96))) -> 5380.4881 | M54: =L54*(1+_xlfn.RRI($N$28-$E$28,$E$52,SUM('2_Calculs'!$L$94:$L$96))) -> 6113.6169 | N54: =M54*(1+_xlfn.RRI($N$28-$E$28,$E$52,SUM('2_Calculs'!$L$94:$L$96))) -> 6946.6397 | P54: =_xlfn.RRI($N$8-$E$8,E54,N54) -> 0.13625694 | R54: =N54=SUM('2_Calculs'!L94:L96) -> TRUE
B57: 2 | D57: Répartition
E59: 2035
D61: Finance | E61: ='2_Calculs'!L95 -> 1734.962
D62: Privé hors finance | E62: ='2_Calculs'!L96 -> 4757.8964
D63: Monaco Telecom | E63: ='2_Calculs'!L94 -> 453.78125
B68: E. | D68: Split total 3 scénarios
F70: Scénario bas | G70: Scénario central | H70: Scénario haut
E71: 2026 | F71: Scénario bas - 2035 | G71: Scénario central - 2035 | H71: Scénario haut - 2035 | K71: 2026 | L71: Scénario bas - 2035 | M71: Scénario central - 2035 | N71: Scénario haut - 2035
D73: DSP | E73: ='2_Calculs'!F9 -> 80 | F73: ='2_Calculs'!L59 -> 368.73304 | G73: ='2_Calculs'!L74 -> 401.33953 | H73: ='2_Calculs'!L89 -> 427.71614 | J73: Privé hors finance | K73: =E80 -> 1677.6 | L73: =F80 -> 2403.8496 | M73: =G80 -> 3858.2419 | N73: =H80 -> 4757.8964
...

Sheet 1_Inputs&Hyp
B2: Inputs & Hypothèses
B6: A. | D6: Baseline 2026
D8: Bloc | E8: Unité | F8: Baseline IT 2026 | G8: Source / commentaire
D9: DSP | E9: kW | F9: 80 | G9: Hypothèse RB sur la base des entretiens
D10: Autres entités publiques (incl. APDP, Caisses sociales, DENJS, DPP) | E10: kW | F10: 20 | G10: Hypothèse RB sur la base des entretiens
D11: Corps Sapeurs Pompiers | E11: kW | F11: 10 | G11: Hypothèse RB sur la base des entretiens
D12: DITN | E12: kW | F12: 80 | G12: Hypothèse RB sur la base des entretiens
D13: CHPG | E13: kW | F13: 80 | G13: Hypothèse RB sur la base des entretiens
D14: Monaco Telecom – besoins propres | E14: kW | F14: =F25*10% -> 160 | G14: Hypothèse RB sur la base des entretiens
D15: Finance | E15: kW | F15: voir onglet calcul | G15: à calculer à partir du modèle
D16: Privé hors finance | E16: kW | F16: voir onglet calcul | G16: à calculer à partir du modèle
D19: Bloc | E19: Unité | F19: Driver / volume 2026 | G19: Source / commentaire
D20: DSP | E20: agents | F20: 628 | G20: Hypothèse RB sur la base des entretiens
D21: Autres entités publiques (incl. APDP, Caisses sociales, DENJS) | E21: kW | G21: Hypothèse RB sur la base des entretiens
D22: Corps Sapeurs Pompiers | E22: kW | G22: Hypothèse RB sur la base des entretiens
D23: DITN | E23: kW | G23: Hypothèse RB sur la base des entretiens
D24: CHPG | E24: kW | G24: Hypothèse RB sur la base des entretiens
D25: Monaco Telecom – besoins propres | E25: kW capacité commerciale | F25: 1600 | G25: Hypothèse RB sur la base des entretiens (10% de la capa commerciale installée)
D26: Finance | E26: salariés | F26: 4534 | G26: 60 454 salariés privés – 4 534 finance (IMSEE, 2024)
D27: Privé hors finance | E27: salariés | F27: 55920 | G27: 60 454 salariés privés – 4 534 finance (IMSEE, 2024)
B31: B. | D31: Hypothèses hors DSP, CHPG
D33: Hypothèse | E33: Unité | F33: Scénario Bas | G33: Scénario Central | H33: Scénario Haut | I33: Source / rationnel
D34: Croissance annuelle effectifs publics | E34: % p.a. | F34: 0.005 | G34: 0.005 | H34: 0.005 | I34: Input (croissance historique)
D35: Croissance annuelle effectifs finance | E35: % p.a. | F35: 0.005 | G35: 0.005 | H35: 0.005 | I35: Input (croissance historique)
D36: Croissance annuelle effectifs privé hors finance | E36: % p.a. | F36: 0.005 | G36: 0.005 | H36: 0.005 | I36: Input (croissance historique)
D37: Croissance annuelle des besoins IT hors IA – public | E37: % p.a. | F37: 0.03 | G37: 0.08 | H37: 0.1 | I37: Hypothèse de travail – besoin IT / utilisateur
D38: Croissance annuelle des besoins IT hors IA – privé finance | E38: % p.a. | F38: 0.05 | G38: 0.1 | H38: 0.15 | I38: Hypothèse de travail – finance plus data-intensive
D39: Croissance annuelle des besoins IT hors IA – privé hors finance | E39: % p.a. | F39: 0.03 | G39: 0.08 | H39: 0.1 | I39: Hypothèse de travail
D40: Besoins IT additionnels liés à l’IA – public | E40: % | F40: 0.05 | G40: 0.1 | H40: 0.15 | I40: Hypothèse de travail
D41: Besoins additionnels liés à l’IA – finance | E41: % | F41: 0.05 | G41: 0.2 | H41: 0.3 | I41: Hypothèse de travail
D42: Besoins additionnels liés à l’IA – hors finance | E42: % | F42: 0.05 | G42: 0.1 | H42: 0.15 | I42: Hypothèse de travail
D43: W IT / salarié finance – 2026 | E43: W / salarié | F43: 80 | G43: 80 | H43: 80 | I43: Input - Morningstar indique dans son 2022 Corporate Sustainability Report 12 224 employés en 2022 ; 6 947 896 kWh de consommation électrique des data centers. 6 947 896 kWh / 12 224 salariés = 568 kWh/salarié/an. Ensnuite 568 / 8 760 = 0,0649 kW = ~65 W/salarié - https://assets.contentstack.io/v3/assets/blt4eb669caa7dc65b2/blt7ae6d78e34f90570/2022_Corporate_Sustainability_Report.pdf
D44: W IT / salarié hors finance – 2026 | E44: W / salarié | F44: 30 | G44: 30 | H44: 30 | I44: Input (borne basse du benchmark)
D45: W IT / agent public – socle non-métier DSP | E45: W / agent | F45: 30 | G45: 30 | H45: 30 | I45: Input (borne basse du benchmark)
... D47: Part adressable Monaco – finance | E47: % | F47: 0.2 | G47: 0.35 | H47: 0.5 | I47: Hypothèse de travail
D48: Part adressable Monaco – privé hors finance | E48: % | F48: 0.1 | G48: 0.2 | H48: 0.35 | I48: Hypothèse de travail | K48: =2^5 -> 32
D49: Part adressable Monaco – surcouche IA public | E49: % | F49: 0.25 | G49: 0.6 | H49: 1 | I49: Externalisée / hybride / locale
D50: Part adressable Monaco – surcouche IA finance | E50: % | F50: 0.15 | G50: 0.4 | H50: 0.75 | I50: Externalisée / hybride / locale
D51: Part adressable Monaco – surcouche IA hors finance | E51: % | F51: 0.1 | G51: 0.3 | H51: 0.6 | I51: Externalisée / hybride / locale
B54: C. | D54: Hypothèses DSP – applications métier (vidéo)
...

Sheet 2_Calculs
B2: Calculs
B6: A. | D6: Baseline besoins d'hébergement 2026
D8: Bloc | E8: Unité | F8: Baseline 2026 | G8: Métier 2026 | H8: Non-métier 2026 (kW)
D9: DSP | E9: kW | F9: ='1_Inputs&Hyp'!F9 -> 80 | G9: =F9-H9 -> 61.16 | H9: =F21*G21/1000 -> 18.84
D10: Autres entités publiques (incl. APDP, Caisses sociales, DENJS, DPP) | E10: kW | F10: ='1_Inputs&Hyp'!F10 -> 20 | G10: =F10-H10 -> 0 | H10: =F10 -> 20
D11: Corps Sapeurs Pompiers | E11: kW | F11: ='1_Inputs&Hyp'!F11 -> 10 | G11: =F11-H11 -> 8 | H11: 2
D12: DITN | E12: kW | F12: ='1_Inputs&Hyp'!F12 -> 80 | G12: =F12-H12 -> 0 | H12: =F12 -> 80
D13: CHPG | E13: kW | F13: ='1_Inputs&Hyp'!F13 -> 80 | G13: =F13-H13 -> 80 | H13: 0
D14: Monaco Telecom | E14: kW | F14: ='1_Inputs&Hyp'!F14 -> 160 | G14: =F14-H14 -> 0 | H14: =F14 -> 160
D15: Finance | E15: kW | F15: ='1_Inputs&Hyp'!F26*F43/1000 -> 362.72 | G15: =F15-H15 -> 0 | H15: =F15 -> 362.72
D16: Privé hors finance | E16: kW | F16: ='1_Inputs&Hyp'!F27*F44/1000 -> 1677.6 | G16: =F16-H16 -> 0 | H16: =F16 -> 1677.6
D17: TOTAL | E17: kW | F17: =SUM(F9:F16) -> 2470.32 | G17: =SUM(G9:G16) -> 149.16 | H17: =SUM(H9:H16) -> 2321.16
D20: Bloc | E20: Unité | F20: Effectifs / driver | G20: W IT / utilisateur | H20: Commentaire
D21: DSP | E21: W IT / Utilisateur | F21: ='1_Inputs&Hyp'!F20 -> 628 | G21: =F45 -> 30 | H21: DSP : résiduel vidéo après socle agents
D22: DENJS | E22: n.a. | H22: Projection générique public
D23: APDP | E23: n.a. | H23: Projection générique public
D24: DITN | E24: n.a. | H24: Projection générique public
D25: CHPG | E25: n.a. | H25: CHPG : activité + intensité + digitalisation métier
D26: Monaco Telecom | E26: n.a. | H26: Besoins propres uniquement
D27: Finance | E27: W IT / Utilisateur | F27: ='1_Inputs&Hyp'!F26 -> 4534 | G27: =F43 -> 80 | H27: Effectifs × W/salarié
D28: Privé hors finance | E28: W IT / Utilisateur | F28: ='1_Inputs&Hyp'!F27 -> 55920 | G28: =F44 -> 30 | H28: Effectifs × W/salarié
D29: TOTAL
B31: B. | D31: Hypothèses par scénario
D33: Hypothèse | E33: Unité | F33: Scénario Bas | G33: Scénario Central | H33: Scénario Haut
D34: Croissance annuelle effectifs publics | E34: % p.a. | F34: ='1_Inputs&Hyp'!F34 -> 0.005 | G34: ='1_Inputs&Hyp'!G34 -> 0.005 | H34: ='1_Inputs&Hyp'!H34 -> 0.005
D35: Croissance annuelle effectifs finance | E35: % p.a. | F35: ='1_Inputs&Hyp'!F35 -> 0.005 | G35: ='1_Inputs&Hyp'!G35 -> 0.005 | H35: ='1_Inputs&Hyp'!H35 -> 0.005
D36: Croissance annuelle effectifs privé hors finance | E36: % p.a. | F36: ='1_Inputs&Hyp'!F36 -> 0.005 | G36: ='1_Inputs&Hyp'!G36 -> 0.005 | H36: ='1_Inputs&Hyp'!H36 -> 0.005
D37: Croissance annuelle des besoins IT hors IA – public | E37: % p.a. | F37: ='1_Inputs&Hyp'!F37 -> 0.03 | G37: ='1_Inputs&Hyp'!G37 -> 0.08 | H37: ='1_Inputs&Hyp'!H37 -> 0.1
D38: Croissance annuelle des besoins IT hors IA – privé finance | E38: % p.a. | F38: ='1_Inputs&Hyp'!F38 -> 0.05 | G38: ='1_Inputs&Hyp'!G38 -> 0.1 | H38: ='1_Inputs&Hyp'!H38 -> 0.15
D39: Croissance annuelle des besoins IT hors IA – privé hors finance | E39: % p.a. | F39: ='1_Inputs&Hyp'!F39 -> 0.03 | G39: ='1_Inputs&Hyp'!G39 -> 0.08 | H39: ='1_Inputs&Hyp'!H39 -> 0.1
D40: Besoins IT additionnels liés à l’IA – public | E40: % | F40: ='1_Inputs&Hyp'!F40 -> 0.05 | G40: ='1_Inputs&Hyp'!G40 -> 0.1 | H40: ='1_Inputs&Hyp'!H40 -> 0.15
D41: Besoins additionnels liés à l’IA – finance | E41: % | F41: ='1_Inputs&Hyp'!F41 -> 0.05 | G41: ='1_Inputs&Hyp'!G41 -> 0.2 | H41: ='1_Inputs&Hyp'!H41 -> 0.3
D42: Besoins additionnels liés à l’IA – hors finance | E42: % | F42: ='1_Inputs&Hyp'!F42 -> 0.05 | G42: ='1_Inputs&Hyp'!G42 -> 0.1 | H42: ='1_Inputs&Hyp'!H42 -> 0.15
D43: W IT / salarié finance – 2026 | E43: W | F43: ='1_Inputs&Hyp'!F43 -> 80 | G43: ='1_Inputs&Hyp'!G43 -> 80 | H43: ='1_Inputs&Hyp'!H43 -> 80
D44: W IT / salarié hors finance – 2026 | E44: W | F44: ='1_Inputs&Hyp'!F44 -> 30 | G44: ='1_Inputs&Hyp'!G44 -> 30 | H44: ='1_Inputs&Hyp'!H44 -> 30
D45: W IT / agent public – socle non-métier DSP | E45: W | F45: ='1_Inputs&Hyp'!F45 -> 30 | G45: ='1_Inputs&Hyp'!G45 -> 30 | H45: ='1_Inputs&Hyp'!H45 -> 30
... D51: Part adressable Monaco – surcouche IA hors finance | E51: % | F51: ='1_Inputs&Hyp'!F51 -> 0.1 | G51: ='1_Inputs&Hyp'!G51 -> 0.3 | H51: ='1_Inputs&Hyp'!H51 -> 0.6
B54: C. | D54: Projection 2035 – besoin IT généré et demande adressable
C56: 1. | D56: Scénario bas
D58: Bloc | E58: Baseline 2026 | F58: Croissance activité / effectifs | G58: Croissance intensité | H58: Facteur de croissance métier | I58: Besoin hors IA 2035 | J58: Surcouche IA | K58: Besoin IA | L58: Besoin total 2035 | M58: Adressable socle [%] | N58: Adressable IA [%] | O58: Demande adressable 2035 [kW IT] | P58: Demande adressable 2035 [MW IT]
...

Sheet 3_Output
B2: Output – projection des besoins IT à horizon 2035
B3: Comparaison des trois scénarios | Besoin généré vs demande adressable à Monaco
B5: A. Synthèse des trois scénarios
B7: Indicateur | C7: Bas | D7: Central | E7: Haut
B8: Besoin IT total généré 2026 (MW IT) | C8: ='2_Calculs'!$F$17/10^3 -> 2.47032 | D8: ='2_Calculs'!$F$17/10^3 -> 2.47032 | E8: ='2_Calculs'!$F$17/10^3 -> 2.47032
B9: Besoin IT total généré 2035 (MW IT) | C9: ='2_Calculs'!L68/10^3 -> 3.9123795 | D9: ='2_Calculs'!L83/10^3 -> 6.1674959 | E9: ='2_Calculs'!L98/10^3 -> 8.2068865
B10: Demande adressable Monaco 2035 (MW IT) | C10: ='2_Calculs'!P68 -> 1.2196333 | D10: ='2_Calculs'!P83 -> 2.3722067 | E10: ='2_Calculs'!P98 -> 4.47834
B12: Taux adressable moyen | C12: =C10/C9 -> 0.31173696 | D12: =D10/D9 -> 0.38463044 | E12: =E10/E9 -> 0.54568076
B13: Croissance besoin généré 2026–2035 (x) | C13: =C9/C8 -> 1.5837541 | D13: =D9/D8 -> 2.4966385 | E13: =E9/E8 -> 3.3221957
B16: B. Demande adressable 2035 par bloc d'entités
B18: Bloc | C18: Bas | D18: Central | E18: Haut
B19: DSP | C19: ='2_Calculs'!P59 -> 0.355564 | D19: ='2_Calculs'!P74 -> 0.38674537 | E19: ='2_Calculs'!P89 -> 0.42771614
B20: Autres entités publiques (incl. APDP, Caisses sociales, DENJS, DPP) | C20: ='2_Calculs'!P60 -> 0.027634691 | D20: ='2_Calculs'!P75 -> 0.044324538 | E20: ='2_Calculs'!P90 -> 0.056722656
B21: Corps Sapeurs Pompiers | C21: ='2_Calculs'!P61 -> 0.018293102 | D21: ='2_Calculs'!P76 -> 0.027948162 | E21: ='2_Calculs'!P91 -> 0.074217607
B22: DITN | C22: ='2_Calculs'!P62 -> 0.11053876 | D22: ='2_Calculs'!P77 -> 0.17729815 | E22: ='2_Calculs'!P92 -> 0.22689062
B23: CHPG | C23: ='2_Calculs'!P63 -> 0.12565759 | D23: ='2_Calculs'!P78 -> 0.19995396 | E23: ='2_Calculs'!P93 -> 0.47469979
B24: Monaco Telecom | C24: ='2_Calculs'!P64 -> 0.21943991 | D24: ='2_Calculs'!P79 -> 0.34456056 | E24: ='2_Calculs'!P94 -> 0.4301057
B25: Finance | C25: ='2_Calculs'!P65 -> 0.1221203 | D25: ='2_Calculs'!P80 -> 0.38465261 | E25: ='2_Calculs'!P95 -> 0.96757498
B26: Privé hors finance | C26: ='2_Calculs'!P66 -> 0.24038496 | D26: ='2_Calculs'!P81 -> 0.80672332 | E26: ='2_Calculs'!P96 -> 1.8204125
B27: TOTAL | C27: =SUM(C19:C26) -> 1.2196333 | D27: =SUM(D19:D26) -> 2.3722067 | E27: =SUM(E19:E26) -> 4.47834
B28: Ctrl | C28: =C27=C10 -> TRUE | D28: =D27=D10 -> TRUE | E28: =E27=E10 -> TRUE
