Workbook
Name _5111cda8_STF_Fuss_1_CN1: #REF!
Name _5111cda8_STF_Gesamtsumme_1_CN1: #REF!
Name _5111cda8_STF_Gesamtsumme_1_CN2: #REF!
Name _5111cda8_STF_Koerper_1_CN1: #REF!
Name _5111cda8_STF_Koerper_1_CN3: #REF!
Name _5111cda8_STF_Koerper_1_CN4: #REF!
Name _5111cda8_STF_Koerper_1_CN5: #REF!
Name _5111cda8_STF_Koerper_1_CN6: #REF!
Name _5111cda8_STF_Koerper_1_CN7: #REF!
Name _5111cda8_STF_Koerper_1_CN8: #REF!
Name _5111cda8_STF_Tabellenkopf_1_CN1: #REF!
Name _5111cda8_STF_Titel_1_CN1: #REF!
Name _5111cda8_STF_Vorspalte_1_CN1: #REF!
Name _CST2006: #REF!
Name _CST2008: #REF!
Name _TAB7: #REF!
Name b: #N/A
Name bébé: #REF!
Name ChoixTraçage: #REF!
Name COMPTE_D_EXPLOITATION_PAR_BRANCHE: #REF!
Name CST: #REF!
Name CST_2006: #REF!
Name D: {#N/A,#N/A,FALSE,"bel";#N/A,#N/A,FALSE,"neth"}
Name DatesGraphiques: CHOOSE(TableauGraphique,#REF!,#REF!)
Name Données_brutes: #REF!
Name Données_volume: #REF!
Name Données_volume_2: #REF!
Name Données_volume_3: #REF!
Name Données_volume_5: #REF!
Name Donnéesbrutes: #REF!
Name Donnéesbrutes_2: #REF!
Name Donnéesbrutes_3: #REF!
Name Donnéesbrutes_5: #REF!
Name DonnéesCNAM: #REF!
Name DonnéesCNAM_2: #REF!
Name DonnéesCNAM_3: #REF!
Name DonnéesCNAM_5: #REF!
Name DonnéesCVS: #REF!
Name DonnéesDemetra_CT: #REF!
Name DonnéesDemetra_CT_2: #REF!
Name DonnéesDemetra_CT_3: #REF!
Name DonnéesDemetra_CT_5: #REF!
Name Fra: "Graphique 2"
Name Graphiques: #REF!
Name IQ_CH: 110000
Name IQ_DAILY: 500000
Name IQ_FH: 100000
Name IQ_MONTH: 15000
Name IQ_WEEK: 50000
Name JHTK: #REF!
Name k: CHOOSE([0]!ll,#REF!,#REF!)
Name KilométrageDébut: #REF!
Name kk: CHOOSE(TableauGraphique,#REF!,#REF!)
Name nom: #REF!
Name NP: #REF!
Name NP_Description: #REF!
Name poupou: #REF!
Name PT_commencerlarangée: ROW(INDEX(#REF!,MATCH("*",#REF!,0),1))+1
Name PT_rangéedextrémité: COUNTA(#REF!)+PT_commencerlarangée-3
Name rien: #REF!

Sheet Cover
D4: Schéma directeur / Plan stratégique à 10 ans cloud et datacenters
D5: Modélisation de la demande IT Horizon 2035

Sheet 1_Inputs&Hyp
B2: Inputs & Hypothèses
B6: A. | D6: Baseline 2026
D8: Bloc | E8: Unité | F8: Baseline IT 2026 | G8: Source / commentaire
D9: DSP | E9: kW | F9: 80 | G9: Hypothèse RB sur la base des entretiens
D10: Autres entités publiques (incl. APDP, Caisses sociales, DENJS) | E10: kW | F10: 20 | G10: Hypothèse RB sur la base des entretiens
D11: Corps Sapeurs Pompiers | E11: kW | F11: 10 | G11: Hypothèse RB sur la base des entretiens
D12: DITN | E12: kW | F12: 80 | G12: Hypothèse RB sur la base des entretiens
D13: CHPG | E13: kW | F13: 80 | G13: Hypothèse RB sur la base des entretiens
D14: Monaco Telecom – besoins propres | E14: kW | F14: =F25*10% -> 160 | G14: Hypothèse RB sur la base des entretiens
D15: Finance | E15: kW | F15: voir onglet calcul | G15: à calculer à partir du modèle
D16: Privé hors finance | E16: kW | F16: voir onglet calcul | G16: à calculer à partir du modèle
D19: Bloc | E19: Unité | F19: Driver / volume 2026 | G19: Source / commentaire
D20: DSP | E20: agents | F20: 628 | G20: Hypothèse RB sur la base des entretiens
D21: Autres entités publiques (incl. APDP, Caisses sociales, DENJS) | E21: kW | G21: Hypothèse RB sur la base des entretiens
D22: Corps Sapeurs Pompiers | E22: kW | G22: Hypothèse RB sur la base des entretiens
D23: DITN | E23: kW | G23: Hypothèse RB sur la base des entretiens
D24: CHPG | E24: kW | G24: Hypothèse RB sur la base des entretiens
D25: Monaco Telecom – besoins propres | E25: kW capacité commerciale | F25: 1600 | G25: Hypothèse RB sur la base des entretiens (10% de la capa commerciale installée)
D26: Finance | E26: salariés | F26: 4534 | G26: 60 454 salariés privés – 4 534 finance (IMSEE, 2024)
D27: Privé hors finance | E27: salariés | F27: 55920 | G27: 60 454 salariés privés – 4 534 finance (IMSEE, 2024)
B31: B. | D31: Hypothèses hors DSP, CHPG
D33: Hypothèse | E33: Unité | F33: Scénario Bas | G33: Scénario Central | H33: Scénario Haut | I33: Source / rationnel
D34: Croissance annuelle effectifs publics | E34: % p.a. | F34: 0 | G34: 0.005 | H34: 0.01 | I34: Hypothèse de travail
D35: Croissance annuelle effectifs finance | E35: % p.a. | F35: 0 | G35: 0.005 | H35: 0.01 | I35: Hypothèse de travail
D36: Croissance annuelle effectifs privé hors finance | E36: % p.a. | F36: 0 | G36: 0.005 | H36: 0.01 | I36: Hypothèse de travail
D37: Croissance annuelle intensité numérique hors IA – public | E37: % p.a. | F37: 0.02 | G37: 0.04 | H37: 0.06 | I37: Hypothèse de travail – besoin IT / utilisateur
D38: Croissance annuelle intensité numérique hors IA – finance | E38: % p.a. | F38: 0.03 | G38: 0.05 | H38: 0.07 | I38: Hypothèse de travail – finance plus data-intensive
D39: Croissance annuelle intensité numérique hors IA – hors finance | E39: % p.a. | F39: 0.02 | G39: 0.04 | H39: 0.06 | I39: Hypothèse de travail
D40: Surcouche IA 2035 – public | E40: % | F40: 0.05 | G40: 0.15 | H40: 0.3 | I40: Hypothèse de travail
D41: Surcouche IA 2035 – finance | E41: % | F41: 0.1 | G41: 0.25 | H41: 0.45 | I41: Hypothèse de travail
D42: Surcouche IA 2035 – hors finance | E42: % | F42: 0.05 | G42: 0.15 | H42: 0.3 | I42: Hypothèse de travail
D43: W IT / salarié finance – 2026 | E43: W / salarié | F43: 80 | G43: 80 | H43: 80 | I43: Hypothèse de travail
D44: W IT / salarié hors finance – 2026 | E44: W / salarié | F44: 30 | G44: 30 | H44: 30 | I44: Hypothèse de travail
D45: W IT / agent public – socle non-métier DSP | E45: W / agent | F45: 30 | G45: 30 | H45: 30 | I45: Hypothèse de travail
... D51: Part adressable Monaco – surcouche IA hors finance | E51: % | F51: 0.1 | G51: 0.3 | H51: 0.6 | I51: Externalisée / hybride / locale
B54: C. | D54: Hypothèses DSP – applications métier (vidéo)
D56: Hypothèse | E56: Unité | F56: Valeur | G56: Type | H56: Source / rationnel
D57: Caméras 2026 | E57: caméras | F57: 1300 | G57: Input | H57: Donnée équipe projet
D58: Ajout annuel de caméras | E58: caméras / an | F58: 50 | G58: Input | H58: Donnée équipe projet
D59: Caméras 2035 | E59: caméras | F59: =F57+9*F58 -> 1750 | G59: Formule | H59: 2026 + 9 × ajout annuel
...

Sheet 2_Calculs
B2: Calculs
B6: A. | D6: Baseline besoins d'hébergement 2026
D8: Bloc | E8: Unité | F8: Baseline 2026 | G8: Métier 2026 | H8: Non-métier 2026 (kW)
D9: DSP | E9: kW | F9: ='1_Inputs&Hyp'!F9 -> 80 | G9: =F9-H9 -> 61.16 | H9: =F21*G21/1000 -> 18.84
D10: Autres entités publiques (incl. APDP, Caisses sociales, DENJS) | E10: kW | F10: ='1_Inputs&Hyp'!F10 -> 20 | G10: =F10-H10 -> 0 | H10: =F10 -> 20
D11: Corps Sapeurs Pompiers | E11: kW | F11: ='1_Inputs&Hyp'!F11 -> 10 | G11: =F11-H11 -> 8 | H11: 2
D12: DITN | E12: kW | F12: ='1_Inputs&Hyp'!F12 -> 80 | G12: =F12-H12 -> 0 | H12: =F12 -> 80
D13: CHPG | E13: kW | F13: ='1_Inputs&Hyp'!F13 -> 80 | G13: =F13-H13 -> 80 | H13: 0
D14: Monaco Telecom | E14: kW | F14: ='1_Inputs&Hyp'!F14 -> 160 | G14: =F14-H14 -> 0 | H14: =F14 -> 160
D15: Finance | E15: kW | F15: ='1_Inputs&Hyp'!F26*F43/1000 -> 362.72 | G15: =F15-H15 -> 0 | H15: =F15 -> 362.72
D16: Privé hors finance | E16: kW | F16: ='1_Inputs&Hyp'!F27*F44/1000 -> 1677.6 | G16: =F16-H16 -> 0 | H16: =F16 -> 1677.6
D17: TOTAL | E17: kW | F17: =SUM(F9:F16) -> 2470.32 | G17: =SUM(G9:G16) -> 149.16 | H17: =SUM(H9:H16) -> 2321.16
D20: Bloc | E20: Unité | F20: Effectifs / driver | G20: W IT / utilisateur | H20: Commentaire
D21: DSP | E21: W IT / Utilisateur | F21: ='1_Inputs&Hyp'!F20 -> 628 | G21: =F45 -> 30 | H21: DSP : résiduel vidéo après socle agents
D22: DENJS | E22: n.a. | H22: Projection générique public
D23: APDP | E23: n.a. | H23: Projection générique public
D24: DITN | E24: n.a. | H24: Projection générique public
D25: CHPG | E25: n.a. | H25: CHPG : activité + intensité + digitalisation métier
D26: Monaco Telecom | E26: n.a. | H26: Besoins propres uniquement
D27: Finance | E27: W IT / Utilisateur | F27: ='1_Inputs&Hyp'!F26 -> 4534 | G27: =F43 -> 80 | H27: Effectifs × W/salarié
D28: Privé hors finance | E28: W IT / Utilisateur | F28: ='1_Inputs&Hyp'!F27 -> 55920 | G28: =F44 -> 30 | H28: Effectifs × W/salarié
D29: TOTAL
B31: B. | D31: Hypothèses par scénario
D33: Hypothèse | E33: Unité | F33: Scénario Bas | G33: Scénario Central | H33: Scénario Haut
D34: Croissance annuelle effectifs publics | E34: % p.a. | F34: ='1_Inputs&Hyp'!F34 -> 0 | G34: ='1_Inputs&Hyp'!G34 -> 0.005 | H34: ='1_Inputs&Hyp'!H34 -> 0.01
D35: Croissance annuelle effectifs finance | E35: % p.a. | F35: ='1_Inputs&Hyp'!F35 -> 0 | G35: ='1_Inputs&Hyp'!G35 -> 0.005 | H35: ='1_Inputs&Hyp'!H35 -> 0.01
D36: Croissance annuelle effectifs privé hors finance | E36: % p.a. | F36: ='1_Inputs&Hyp'!F36 -> 0 | G36: ='1_Inputs&Hyp'!G36 -> 0.005 | H36: ='1_Inputs&Hyp'!H36 -> 0.01
D37: Croissance annuelle intensité numérique hors IA – public | E37: % p.a. | F37: ='1_Inputs&Hyp'!F37 -> 0.02 | G37: ='1_Inputs&Hyp'!G37 -> 0.04 | H37: ='1_Inputs&Hyp'!H37 -> 0.06
D38: Croissance annuelle intensité numérique hors IA – finance | E38: % p.a. | F38: ='1_Inputs&Hyp'!F38 -> 0.03 | G38: ='1_Inputs&Hyp'!G38 -> 0.05 | H38: ='1_Inputs&Hyp'!H38 -> 0.07
D39: Croissance annuelle intensité numérique hors IA – hors finance | E39: % p.a. | F39: ='1_Inputs&Hyp'!F39 -> 0.02 | G39: ='1_Inputs&Hyp'!G39 -> 0.04 | H39: ='1_Inputs&Hyp'!H39 -> 0.06
D40: Surcouche IA 2035 – public | E40: % | F40: ='1_Inputs&Hyp'!F40 -> 0.05 | G40: ='1_Inputs&Hyp'!G40 -> 0.15 | H40: ='1_Inputs&Hyp'!H40 -> 0.3
D41: Surcouche IA 2035 – finance | E41: % | F41: ='1_Inputs&Hyp'!F41 -> 0.1 | G41: ='1_Inputs&Hyp'!G41 -> 0.25 | H41: ='1_Inputs&Hyp'!H41 -> 0.45
D42: Surcouche IA 2035 – hors finance | E42: % | F42: ='1_Inputs&Hyp'!F42 -> 0.05 | G42: ='1_Inputs&Hyp'!G42 -> 0.15 | H42: ='1_Inputs&Hyp'!H42 -> 0.3
D43: W IT / salarié finance – 2026 | E43: W | F43: ='1_Inputs&Hyp'!F43 -> 80 | G43: ='1_Inputs&Hyp'!G43 -> 80 | H43: ='1_Inputs&Hyp'!H43 -> 80
D44: W IT / salarié hors finance – 2026 | E44: W | F44: ='1_Inputs&Hyp'!F44 -> 30 | G44: ='1_Inputs&Hyp'!G44 -> 30 | H44: ='1_Inputs&Hyp'!H44 -> 30
D45: W IT / agent public – socle non-métier DSP | E45: W | F45: ='1_Inputs&Hyp'!F45 -> 30 | G45: ='1_Inputs&Hyp'!G45 -> 30 | H45: ='1_Inputs&Hyp'!H45 -> 30
... D51: Part adressable Monaco – surcouche IA hors finance | E51: % | F51: ='1_Inputs&Hyp'!F51 -> 0.1 | G51: ='1_Inputs&Hyp'!G51 -> 0.3 | H51: ='1_Inputs&Hyp'!H51 -> 0.6
B54: C. | D54: Projection 2035 – besoin IT généré et demande adressable
C56: 1. | D56: Scénario bas
D58: Bloc | E58: Baseline 2026 | F58: Croissance activité / effectifs | G58: Croissance intensité | H58: Facteur de croissance métier | I58: Besoin hors IA 2035 | J58: Surcouche IA | K58: Besoin IA | L58: Besoin total 2035 | M58: Adressable socle [%] | N58: Adressable IA [%] | O58: Demande adressable 2035 [kW IT] | P58: Demande adressable 2035 [MW IT]
...

Sheet 3_Output
B2: Output – projection des besoins IT à horizon 2035
B3: Comparaison des trois scénarios | Besoin généré vs demande adressable à Monaco
B5: A. Synthèse des trois scénarios
B7: Indicateur | C7: Bas | D7: Central | E7: Haut
B8: Besoin IT total généré 2026 (MW IT) | C8: ='2_Calculs'!$F$17/10^3 -> 2.47032 | D8: ='2_Calculs'!$F$17/10^3 -> 2.47032 | E8: ='2_Calculs'!$F$17/10^3 -> 2.47032
B9: Besoin IT total généré 2035 (MW IT) | C9: ='2_Calculs'!L68/10^3 -> 3.4662904 | D9: ='2_Calculs'!L83/10^3 -> 4.7051533 | E9: ='2_Calculs'!L98/10^3 -> 6.7990603
B10: Demande adressable Monaco 2035 (MW IT) | C10: ='2_Calculs'!P68 -> 1.121376 | D10: ='2_Calculs'!P83 -> 1.9062277 | E10: ='2_Calculs'!P98 -> 3.9300297
B12: Taux adressable moyen | C12: =C10/C9 -> 0.32350897 | D12: =D10/D9 -> 0.40513614 | E12: =E10/E9 -> 0.57802542
B13: Croissance besoin généré 2026–2035 (x) | C13: =C9/C8 -> 1.4031746 | D13: =D9/D8 -> 1.9046736 | E13: =E9/E8 -> 2.7522994
B16: B. Demande adressable 2035 par bloc d'entités
B18: Bloc | C18: Bas | D18: Central | E18: Haut
B19: DSP | C19: ='2_Calculs'!P59 -> 0.35232911 | D19: ='2_Calculs'!P74 -> 0.38532603 | E19: ='2_Calculs'!P89 -> 0.46835826
B20: Autres entités publiques (incl. APDP, Caisses sociales, DENJS) | C20: ='2_Calculs'!P60 -> 0.024200625 | D20: ='2_Calculs'!P75 -> 0.03245272 | E20: ='2_Calculs'!P90 -> 0.048041715
B21: Corps Sapeurs Pompiers | C21: ='2_Calculs'!P61 -> 0.017949696 | D21: ='2_Calculs'!P76 -> 0.027426519 | E21: ='2_Calculs'!P91 -> 0.08229021
B22: DITN | C22: ='2_Calculs'!P62 -> 0.096802498 | D22: ='2_Calculs'!P77 -> 0.12981088 | E22: ='2_Calculs'!P92 -> 0.19216686
B23: CHPG | C23: ='2_Calculs'!P63 -> 0.12565759 | D23: ='2_Calculs'!P78 -> 0.20561304 | E23: ='2_Calculs'!P93 -> 0.53661716
B24: Monaco Telecom | C24: ='2_Calculs'!P64 -> 0.19217089 | D24: ='2_Calculs'!P79 -> 0.24890343 | E24: ='2_Calculs'!P94 -> 0.34885676
B25: Finance | C25: ='2_Calculs'!P65 -> 0.10175248 | D25: ='2_Calculs'!P80 -> 0.2648392 | E25: ='2_Calculs'!P95 -> 0.61080514
B26: Privé hors finance | C26: ='2_Calculs'!P66 -> 0.21051317 | D26: ='2_Calculs'!P81 -> 0.61185584 | E26: ='2_Calculs'!P96 -> 1.6428936
B27: TOTAL | C27: =SUM(C19:C26) -> 1.121376 | D27: =SUM(D19:D26) -> 1.9062277 | E27: =SUM(E19:E26) -> 3.9300297
B28: Ctrl | C28: =C27=C10 -> TRUE | D28: =D27=D10 -> TRUE | E28: =E27=E10 -> TRUE
